Workbook
Name dd_OrderMonth: Dashboard!$E$7
Name dd_PaymentMethod: Dashboard!$B$7
Name Slicer_Category: #N/A
Name Slicer_Customer_Age_Group: #N/A
Name Slicer_Order_Month: #N/A
Name Slicer_Order_Status: #N/A
Name Slicer_Order_Year: #N/A
Name Slicer_Payment_Method1: #N/A

Sheet Dashboard
B2: E-COMMERCE SALES ANALYTICS
B4: Sales Performance • Revenue • Profitability • Customer Insights
B5: Business Performance Overview
Q7: SLICER
B8: TOTAL REVENUE | E8: TOTAL PROFIT | H8: UNITS SOLD | K8: TOTAL ORDERS | N8: PROFIT MARGIN
B10: =GETPIVOTDATA("Total Revenue ",Analysis!$A$1) -> 13596053 | E10: =GETPIVOTDATA("Total Profit ",Analysis!$A$1) -> 4935773 | H10: =GETPIVOTDATA("Units Sold ",Analysis!$A$1) -> 8906 | K10: =GETPIVOTDATA("[Measures].[Count of Order_ID]",Analysis!$O$14) -> 5000 | N10: =IFERROR(E10/B10,0) -> 0.36302984
B94: Source: E-Commerce Sales Dataset | Analysis Period: 2025–2026
E96: Built using Microsoft Excel | Data Analysis & Visualization

Sheet Business_Insights
B1: E-Commerce Sales Analytics — Business Insights
B5: Executive Summary The e-commerce business generated approximately ₹13.60M in net revenue from 5,000 orders, selling 8,906 units and generating approximately ₹4.94M in profit, resulting in an overall 36.3% profit margin.
B9: # | C9: Business Area | D9: Insight | E9: Business Recommendation
B10: 1 | C10: Revenue | D10: Identify the highest-revenue category | E10: Focus inventory and marketing on the strongest category
B11: 2 | C11: Profitability | D11: Identify the most profitable category | E11: Prioritize high-margin products
B12: 3 | C12: Products | D12: Identify the Top 10 products | E12: Maintain stock availability for high-performing products
B13: 4 | C13: Geography | D13: Identify the highest-revenue cities | E13: Increase marketing in strong-performing locations
B14: 5 | C14: Customers | D14: Identify the strongest age group | E14: Target campaigns toward the strongest customer segment
B15: 6 | C15: Payments | D15: Identify the leading payment method | E15: Optimize the checkout experience for preferred methods
B16: 7 | C16: Discounts | D16: Analyze how discounts affect profit | E16: Avoid excessive discounting where margins decline
B17: 8 | C17: Orders | D17: Identify the dominant order status | E17: Investigate cancelled/pending orders if significant
B20: Key Takeaways
B22: • Generated ₹13.60M revenue and ₹4.94M profit with a 36% overall profit margin across 5,000 orders. • Electronics emerged as the leading revenue-generating category, making it a key contributor to overall business performance. • The 26–35 customer segment generated the highest revenue, identifying a high-value customer group for targeted marketing. • Revenue showed noticeable seasonal fluctuations, with performance peaking around October–November and declining during several low-performing months. • Profitability was strongest at moderate discount levels, while higher discounts showed a clear decline in profit, highlighting the need for controlled promotional pricing.

Sheet Analysis
A1: Total Revenue | B1: Total Profit | C1: Units Sold | F1: Row Labels | G1: Total Revenue | H1: Total Profit | I1: Units Sold | K1: Row Labels | L1: Total Revenue | O1: Row Labels | P1: Total Revenue | Q1: Total Profit
A2: 13596053 | B2: 4935773 | C2: 8906 | F2: Air Fryer | G2: 1210298.2 | H2: 309398.25 | I2: 231 | K2: Cash on Delivery | L2: 1375731.4 | O2: 0 | P2: 1993556 | Q2: 855796
F3: Running Shoes | G3: 1077993.2 | H3: 369093.15 | I3: 417 | K3: Credit Card | L3: 2874731.7 | O3: 0.05 | P3: 3110280 | Q3: 1250710.1
A4: Row Labels | B4: Total evenue | C4: Total Profit | F4: Smart Watch | G4: 1076463.7 | H4: 307863.7 | I4: 366 | K4: Debit Card | L4: 2303140.5 | O4: 0.1 | P4: 3678600.6 | Q4: 1385720.6
A5: Apr | B5: 1497043.4 | C5: 548253.45 | F5: Wireless Headphones | G5: 1054328.1 | H5: 319628.1 | I5: 474 | K5: Net Banking | L5: 1626252.7 | O5: 0.15 | P5: 2378991 | Q5: 804041.05
A6: Feb | B6: 1386576.6 | C6: 494146.65 | F6: Coffee Maker | G6: 736714.45 | H6: 210214.45 | I6: 234 | K6: UPI | L6: 4574115.4 | O6: 0.2 | P6: 1412241.6 | Q6: 410011.6
A7: Jan | B7: 1497672.9 | C7: 548002.9 | F7: Non-Stick Cookware Set | G7: 693428.7 | H7: 212828.7 | I7: 178 | K7: Wallet | L7: 842081.3 | O7: 0.25 | P7: 646150.5 | Q7: 162900.5
A8: Jun | B8: 1431582.4 | C8: 529022.4 | F8: Bluetooth Speaker | G8: 596950.65 | H8: 197110.65 | I8: 357 | K8: Grand Total | L8: 13596053 | O8: 0.3 | P8: 376233.2 | Q8: 66593.2
A9: Mar | B9: 1704774.4 | C9: 617444.4 | F9: Denim Jeans | G9: 583907.9 | H9: 238457.9 | I9: 329 | O9: Grand Total | P9: 13596053 | Q9: 4935773
A10: May | B10: 1645399.5 | C10: 594689.5 | F10: Dumbbell Set | G10: 560150.85 | H10: 193300.85 | I10: 253
A11: Aug | B11: 857893.8 | C11: 305083.8 | F11: Cricket Bat | G11: 544912.2 | H11: 193662.2 | I11: 281 | K11: Row Labels | L11: Total Revenue | M11: Units Sold
A12: Dec | B12: 737109.3 | C12: 267219.3 | F12: Grand Total | G12: 8135147.9 | H12: 2551558 | I12: 3120 | K12: 18-25 | L12: 3011851.8 | M12: 2010
A13: Jul | B13: 758875.4 | C13: 276865.4 | K13: 26-35 | L13: 5843467.8 | M13: 3816
A14: Nov | B14: 714928.3 | C14: 256768.3 | K14: 36-45 | L14: 3849209.6 | M14: 2492 | O14: Count of Order_ID
A15: Oct | B15: 692871.6 | C15: 251681.6 | F15: Row Labels | G15: Total Revenue | H15: Total Profit | K15: 46-55 | L15: 858317.55 | M15: 561 | O15: 5000
A16: Sep | B16: 671325.3 | C16: 246595.3 | F16: Delhi | G16: 719261.95 | H16: 255721.95 | K16: 56+ | L16: 33206.3 | M16: 27
A17: Grand Total | B17: 13596053 | C17: 4935773 | F17: Surat | G17: 684742.65 | H17: 245782.65 | K17: Grand Total | L17: 13596053 | M17: 8906
F18: Kochi | G18: 646354.35 | H18: 230014.35
F19: Coimbatore | G19: 622928.8 | H19: 220518.8
A20: Row Labels | B20: Total Revenue | C20: Total Profit | D20: Units Sold | F20: Mumbai | G20: 622816.6 | H20: 225936.6 | K20: Row Labels | L20: Total Revenue | M20: Units Sold
A21: Beauty | B21: 1248415.3 | C21: 592215.3 | D21: 1643 | F21: Bengaluru | G21: 614128.15 | H21: 224128.15 | K21: Cancelled | L21: 615298.4 | M21: 403
A22: Books | B22: 1120834.9 | C22: 538214.95 | D22: 1347 | F22: Ahmedabad | G22: 596833.5 | H22: 215423.5 | K22: Delivered | L22: 12236356 | M22: 8014
A23: Electronics | B23: 3380694.3 | C23: 1064314.3 | D23: 1782 | F23: Nagpur | G23: 593655.05 | H23: 211755.05 | K23: Returned | L23: 744398.75 | M23: 489
A24: Fashion | B24: 2739757.3 | C24: 1055427.3 | D24: 1654 | F24: Ranchi | G24: 593018.15 | H24: 209088.15 | K24: Grand Total | L24: 13596053 | M24: 8906
A25: Home & Kitchen | B25: 3223975.9 | C25: 968405.9 | D25: 1092 | F25: Lucknow | G25: 585140.25 | H25: 208890.25
A26: Sports & Fitness | B26: 1882375.3 | C26: 717195.25 | D26: 1388 | F26: Grand Total | G26: 6278879.4 | H26: 2247259.5
A27: Grand Total | B27: 13596053 | C27: 4935773 | D27: 8906

Sheet Ecommerce_Sales
A1: Order_ID | B1: Order_Date | C1: Customer_ID | D1: Customer_Name | E1: Gender | F1: Age | G1: City | H1: Region | I1: Product_ID | J1: Product_Name | K1: Category | L1: Sub_Category | M1: Quantity | N1: Unit_Price | O1: Discount | P1: Cost | Q1: Payment_Method | R1: Order_Status | S1: Sales_Channel | T1: Rating | U1: Gross_Sales | V1: Discount_Amount | W1: Net_Revenue | X1: Total_Cost | Y1: Profit | Z1: Profit_Margin | AA1: Order_Month | AB1: Order_Year | AC1: Customer_Age_Group
A2: ORD104877 | B2: 45658 | C2: CUST1411 | D2: Riya Verma | E2: Female | F2: 24 | G2: Bokaro | H2: East | I2: P012 | J2: Air Fryer | K2: Home & Kitchen | L2: Kitchen | M2: 1 | N2: 5999 | O2: 0.1 | P2: 3900 | Q2: UPI | R2: Delivered | S2: Mobile App | T2: 3 | U2: =M2*N2 -> 5999 | V2: =tbl_EcommerceSales[[#This Row],[Gross_Sales]]*tbl_EcommerceSales[[#This Row],[Discount]] -> 599.9 | W2: =tbl_EcommerceSales[[#This Row],[Gross_Sales]]-tbl_EcommerceSales[[#This Row],[Discount_Amount]] -> 5399.1 | X2: =tbl_EcommerceSales[[#This Row],[Quantity]] * _xlfn.XLOOKUP(tbl_EcommerceSales[[#This Row],[Product_ID]], Product_Master!A:A, Product_Master!F:F) -> 3900 | Y2: =tbl_EcommerceSales[[#This Row],[Net_Revenue]]-tbl_EcommerceSales[[#This Row],[Total_Cost]] -> 1499.1 | Z2: =IFERROR(#REF!/tbl_EcommerceSales[[#This Row],[Total_Cost]], 0) -> 0 | AA2: =TEXT(tbl_EcommerceSales[[#This Row],[Order_Date]],"mmm") -> Jan | AB2: =YEAR(tbl_EcommerceSales[[#This Row],[Order_Date]]) -> 2025 | AC2: =IF(tbl_EcommerceSales[[#This Row],[Age]]<18,"Under 18",IF(tbl_EcommerceSales[[#This Row],[Age]]<=25,"18-25",IF(tbl_EcommerceSales[[#This Row],[Age]]<=35,"26-35",IF(tbl_EcommerceSales[[#This Row],[Age]]<=45,"36-45",IF(tbl_EcommerceSales[[#This Row],[Age]]<=55,"46-55","56+"))))) -> 18-25
A3: ORD104594 | B3: 45658 | C3: CUST1943 | D3: Aditi Saxena | E3: Female | F3: 47 | G3: Amritsar | H3: North | I3: P025 | J3: Moisturizer | K3: Beauty | L3: Skincare | M3: 1 | N3: 699 | O3: 0.1 | P3: 310 | Q3: Debit Card | R3: Delivered | S3: Mobile App | T3: 4 | U3: =M3*N3 -> 699 | V3: =tbl_EcommerceSales[[#This Row],[Gross_Sales]]*tbl_EcommerceSales[[#This Row],[Discount]] -> 69.9 | W3: =tbl_EcommerceSales[[#This Row],[Gross_Sales]]-tbl_EcommerceSales[[#This Row],[Discount_Amount]] -> 629.1 | X3: =tbl_EcommerceSales[[#This Row],[Quantity]] * _xlfn.XLOOKUP(tbl_EcommerceSales[[#This Row],[Product_ID]], Product_Master!A:A, Product_Master!F:F) -> 310 | Y3: =tbl_EcommerceSales[[#This Row],[Net_Revenue]]-tbl_EcommerceSales[[#This Row],[Total_Cost]] -> 319.1 | Z3: =IFERROR(#REF!/tbl_EcommerceSales[[#This Row],[Total_Cost]], 0) -> 0 | AA3: =TEXT(tbl_EcommerceSales[[#This Row],[Order_Date]],"mmm") -> Jan | AB3: =YEAR(tbl_EcommerceSales[[#This Row],[Order_Date]]) -> 2025 | AC3: =IF(tbl_EcommerceSales[[#This Row],[Age]]<18,"Under 18",IF(tbl_EcommerceSales[[#This Row],[Age]]<=25,"18-25",IF(tbl_EcommerceSales[[#This Row],[Age]]<=35,"26-35",IF(tbl_EcommerceSales[[#This Row],[Age]]<=45,"36-45",IF(tbl_EcommerceSales[[#This Row],[Age]]<=55,"46-55","56+"))))) -> 46-55
A4: ORD100846 | B4: 45658 | C4: CUST0744 | D4: Sanya Malhotra | E4: Male | F4: 24 | G4: Amritsar | H4: North | I4: P025 | J4: Moisturizer | K4: Beauty | L4: Skincare | M4: 1 | N4: 699 | O4: 0.2 | P4: 310 | Q4: UPI | R4: Delivered | S4: Mobile App | T4: 5 | U4: =M4*N4 -> 699 | V4: =tbl_EcommerceSales[[#This Row],[Gross_Sales]]*tbl_EcommerceSales[[#This Row],[Discount]] -> 139.8 | W4: =tbl_EcommerceSales[[#This Row],[Gross_Sales]]-tbl_EcommerceSales[[#This Row],[Discount_Amount]] -> 559.2 | X4: =tbl_EcommerceSales[[#This Row],[Quantity]] * _xlfn.XLOOKUP(tbl_EcommerceSales[[#This Row],[Product_ID]], Product_Master!A:A, Product_Master!F:F) -> 310 | Y4: =tbl_EcommerceSales[[#This Row],[Net_Revenue]]-tbl_EcommerceSales[[#This Row],[Total_Cost]] -> 249.2 | Z4: =IFERROR(#REF!/tbl_EcommerceSales[[#This Row],[Total_Cost]], 0) -> 0 | AA4: =TEXT(tbl_EcommerceSales[[#This Row],[Order_Date]],"mmm") -> Jan | AB4: =YEAR(tbl_EcommerceSales[[#This Row],[Order_Date]]) -> 2025 | AC4: =IF(tbl_EcommerceSales[[#This Row],[Age]]<18,"Under 18",IF(tbl_EcommerceSales[[#This Row],[Age]]<=25,"18-25",IF(tbl_EcommerceSales[[#This Row],[Age]]<=35,"26-35",IF(tbl_EcommerceSales[[#This Row],[Age]]<=45,"36-45",IF(tbl_EcommerceSales[[#This Row],[Age]]<=55,"46-55","56+"))))) -> 18-25
A5: ORD101485 | B5: 45658 | C5: CUST1433 | D5: Meera Singh | E5: Female | F5: 42 | G5: Patna | H5: East | I5: P008 | J5: Cotton T-Shirt | K5: Fashion | L5: Clothing | M5: 2 | N5: 799 | O5: 0.1 | P5: 780 | Q5: UPI | R5: Delivered | S5: Website | T5: 5 | U5: =M5*N5 -> 1598 | V5: =tbl_EcommerceSales[[#This Row],[Gross_Sales]]*tbl_EcommerceSales[[#This Row],[Discount]] -> 159.8 | W5: =tbl_EcommerceSales[[#This Row],[Gross_Sales]]-tbl_EcommerceSales[[#This Row],[Discount_Amount]] -> 1438.2 | X5: =tbl_EcommerceSales[[#This Row],[Quantity]] * _xlfn.XLOOKUP(tbl_EcommerceSales[[#This Row],[Product_ID]], Product_Master!A:A, Product_Master!F:F) -> 780 | Y5: =tbl_EcommerceSales[[#This Row],[Net_Revenue]]-tbl_EcommerceSales[[#This Row],[Total_Cost]] -> 658.2 | Z5: =IFERROR(#REF!/tbl_EcommerceSales[[#This Row],[Total_Cost]], 0) -> 0 | AA5: =TEXT(tbl_EcommerceSales[[#This Row],[Order_Date]],"mmm") -> Jan | AB5: =YEAR(tbl_EcommerceSales[[#This Row],[Order_Date]]) -> 2025 | AC5: =IF(tbl_EcommerceSales[[#This Row],[Age]]<18,"Under 18",IF(tbl_EcommerceSales[[#This Row],[Age]]<=25,"18-25",IF(tbl_EcommerceSales[[#This Row],[Age]]<=35,"26-35",IF(tbl_EcommerceSales[[#This Row],[Age]]<=45,"36-45",IF(tbl_EcommerceSales[[#This Row],[Age]]<=55,"46-55","56+"))))) -> 36-45
A6: ORD104728 | B6: 45658 | C6: CUST0422 | D6: Kabir Gupta | E6: Male | F6: 34 | G6: Kolkata | H6: East | I6: P021 | J6: Face Wash | K6: Beauty | L6: Skincare | M6: 2 | N6: 499 | O6: 0.15 | P6: 440 | Q6: UPI | R6: Delivered | S6: Mobile App | T6: 5 | U6: =M6*N6 -> 998 | V6: =tbl_EcommerceSales[[#This Row],[Gross_Sales]]*tbl_EcommerceSales[[#This Row],[Discount]] -> 149.7 | W6: =tbl_EcommerceSales[[#This Row],[Gross_Sales]]-tbl_EcommerceSales[[#This Row],[Discount_Amount]] -> 848.3 | X6: =tbl_EcommerceSales[[#This Row],[Quantity]] * _xlfn.XLOOKUP(tbl_EcommerceSales[[#This Row],[Product_ID]], Product_Master!A:A, Product_Master!F:F) -> 440 | Y6: =tbl_EcommerceSales[[#This Row],[Net_Revenue]]-tbl_EcommerceSales[[#This Row],[Total_Cost]] -> 408.3 | Z6: =IFERROR(#REF!/tbl_EcommerceSales[[#This Row],[Total_Cost]], 0) -> 0 | AA6: =TEXT(tbl_EcommerceSales[[#This Row],[Order_Date]],"mmm") -> Jan | AB6: =YEAR(tbl_EcommerceSales[[#This Row],[Order_Date]]) -> 2025 | AC6: =IF(tbl_EcommerceSales[[#This Row],[Age]]<18,"Under 18",IF(tbl_EcommerceSales[[#This Row],[Age]]<=25,"18-25",IF(tbl_EcommerceSales[[#This Row],[Age]]<=35,"26-35",IF(tbl_EcommerceSales[[#This Row],[Age]]<=45,"36-45",IF(tbl_EcommerceSales[[#This Row],[Age]]<=55,"46-55","56+"))))) -> 26-35
A7: ORD100558 | B7: 45658 | C7: CUST0105 | D7: Zoya Singh | E7: Male | F7: 42 | G7: Amritsar | H7: North | I7: P022 | J7: Sunscreen SPF 50 | K7: Beauty | L7: Skincare | M7: 1 | N7: 799 | O7: 0.15 | P7: 360 | Q7: UPI | R7: Delivered | S7: Mobile App | T7: 5 | U7: =M7*N7 -> 799 | V7: =tbl_EcommerceSales[[#This Row],[Gross_Sales]]*tbl_EcommerceSales[[#This Row],[Discount]] -> 119.85 | W7: =tbl_EcommerceSales[[#This Row],[Gross_Sales]]-tbl_EcommerceSales[[#This Row],[Discount_Amount]] -> 679.15 | X7: =tbl_EcommerceSales[[#This Row],[Quantity]] * _xlfn.XLOOKUP(tbl_EcommerceSales[[#This Row],[Product_ID]], Product_Master!A:A, Product_Master!F:F) -> 360 | Y7: =tbl_EcommerceSales[[#This Row],[Net_Revenue]]-tbl_EcommerceSales[[#This Row],[Total_Cost]] -> 319.15 | Z7: =IFERROR(#REF!/tbl_EcommerceSales[[#This Row],[Total_Cost]], 0) -> 0 | AA7: =TEXT(tbl_EcommerceSales[[#This Row],[Order_Date]],"mmm") -> Jan | AB7: =YEAR(tbl_EcommerceSales[[#This Row],[Order_Date]]) -> 2025 | AC7: =IF(tbl_EcommerceSales[[#This Row],[Age]]<18,"Under 18",IF(tbl_EcommerceSales[[#This Row],[Age]]<=25,"18-25",IF(tbl_EcommerceSales[[#This Row],[Age]]<=35,"26-35",IF(tbl_EcommerceSales[[#This Row],[Age]]<=45,"36-45",IF(tbl_EcommerceSales[[#This Row],[Age]]<=55,"46-55","56+"))))) -> 36-45
A8: ORD101536 | B8: 45658 | C8: CUST1894 | D8: Kabir Gupta | E8: Male | F8: 44 | G8: Hyderabad | H8: South | I8: P007 | J8: Running Shoes | K8: Fashion | L8: Footwear | M8: 1 | N8: 2899 | O8: 0.05 | P8: 1700 | Q8: Cash on Delivery | R8: Delivered | S8: Mobile App | T8: 5 | U8: =M8*N8 -> 2899 | V8: =tbl_EcommerceSales[[#This Row],[Gross_Sales]]*tbl_EcommerceSales[[#This Row],[Discount]] -> 144.95 | W8: =tbl_EcommerceSales[[#This Row],[Gross_Sales]]-tbl_EcommerceSales[[#This Row],[Discount_Amount]] -> 2754.05 | X8: =tbl_EcommerceSales[[#This Row],[Quantity]] * _xlfn.XLOOKUP(tbl_EcommerceSales[[#This Row],[Product_ID]], Product_Master!A:A, Product_Master!F:F) -> 1700 | Y8: =tbl_EcommerceSales[[#This Row],[Net_Revenue]]-tbl_EcommerceSales[[#This Row],[Total_Cost]] -> 1054.05 | Z8: =IFERROR(#REF!/tbl_EcommerceSales[[#This Row],[Total_Cost]], 0) -> 0 | AA8: =TEXT(tbl_EcommerceSales[[#This Row],[Order_Date]],"mmm") -> Jan | AB8: =YEAR(tbl_EcommerceSales[[#This Row],[Order_Date]]) -> 2025 | AC8: =IF(tbl_EcommerceSales[[#This Row],[Age]]<18,"Under 18",IF(tbl_EcommerceSales[[#This Row],[Age]]<=25,"18-25",IF(tbl_EcommerceSales[[#This Row],[Age]]<=35,"26-35",IF(tbl_EcommerceSales[[#This Row],[Age]]<=45,"36-45",IF(tbl_EcommerceSales[[#This Row],[Age]]<=55,"46-55","56+"))))) -> 36-45
A9: ORD100734 | B9: 45658 | C9: CUST0559 | D9: Isha Mehta | E9: Male | F9: 22 | G9: Kolkata | H9: East | I9: P001 | J9: Wireless Headphones | K9: Electronics | L9: Audio | M9: 1 | N9: 2499 | O9: 0.1 | P9: 1550 | Q9: UPI | R9: Delivered | S9: Mobile App | T9: 3 | U9: =M9*N9 -> 2499 | V9: =tbl_EcommerceSales[[#This Row],[Gross_Sales]]*tbl_EcommerceSales[[#This Row],[Discount]] -> 249.9 | W9: =tbl_EcommerceSales[[#This Row],[Gross_Sales]]-tbl_EcommerceSales[[#This Row],[Discount_Amount]] -> 2249.1 | X9: =tbl_EcommerceSales[[#This Row],[Quantity]] * _xlfn.XLOOKUP(tbl_EcommerceSales[[#This Row],[Product_ID]], Product_Master!A:A, Product_Master!F:F) -> 1550 | Y9: =tbl_EcommerceSales[[#This Row],[Net_Revenue]]-tbl_EcommerceSales[[#This Row],[Total_Cost]] -> 699.1 | Z9: =IFERROR(#REF!/tbl_EcommerceSales[[#This Row],[Total_Cost]], 0) -> 0 | AA9: =TEXT(tbl_EcommerceSales[[#This Row],[Order_Date]],"mmm") -> Jan | AB9: =YEAR(tbl_EcommerceSales[[#This Row],[Order_Date]]) -> 2025 | AC9: =IF(tbl_EcommerceSales[[#This Row],[Age]]<18,"Under 18",IF(tbl_EcommerceSales[[#This Row],[Age]]<=25,"18-25",IF(tbl_EcommerceSales[[#This Row],[Age]]<=35,"26-35",IF(tbl_EcommerceSales[[#This Row],[Age]]<=45,"36-45",IF(tbl_EcommerceSales[[#This Row],[Age]]<=55,"46-55","56+"))))) -> 18-25
A10: ORD104917 | B10: 45658 | C10: CUST2028 | D10: Rahul Kumar | E10: Male | F10: 20 | G10: Nagpur | H10: West | I10: P030 | J10: Self Help Book | K10: Books | L10: Self Development | M10: 1 | N10: 599 | O10: 0.05 | P10: 260 | Q10: UPI | R10: Returned | S10: Website | T10: 5 | U10: =M10*N10 -> 599 | V10: =tbl_EcommerceSales[[#This Row],[Gross_Sales]]*tbl_EcommerceSales[[#This Row],[Discount]] -> 29.95 | W10: =tbl_EcommerceSales[[#This Row],[Gross_Sales]]-tbl_EcommerceSales[[#This Row],[Discount_Amount]] -> 569.05 | X10: =tbl_EcommerceSales[[#This Row],[Quantity]] * _xlfn.XLOOKUP(tbl_EcommerceSales[[#This Row],[Product_ID]], Product_Master!A:A, Product_Master!F:F) -> 260 | Y10: =tbl_EcommerceSales[[#This Row],[Net_Revenue]]-tbl_EcommerceSales[[#This Row],[Total_Cost]] -> 309.05 | Z10: =IFERROR(#REF!/tbl_EcommerceSales[[#This Row],[Total_Cost]], 0) -> 0 | AA10: =TEXT(tbl_EcommerceSales[[#This Row],[Order_Date]],"mmm") -> Jan | AB10: =YEAR(tbl_EcommerceSales[[#This Row],[Order_Date]]) -> 2025 | AC10: =IF(tbl_EcommerceSales[[#This Row],[Age]]<18,"Under 18",IF(tbl_EcommerceSales[[#This Row],[Age]]<=25,"18-25",IF(tbl_EcommerceSales[[#This Row],[Age]]<=35,"26-35",IF(tbl_EcommerceSales[[#This Row],[Age]]<=45,"36-45",IF(tbl_EcommerceSales[[#This Row],[Age]]<=55,"46-55","56+"))))) -> 18-25
A11: ORD100475 | B11: 45658 | C11: CUST1049 | D11: Meera Singh | E11: Male | F11: 45 | G11: Dehradun | H11: North | I11: P001 | J11: Wireless Headphones | K11: Electronics | L11: Audio | M11: 1 | N11: 2499 | O11: 0.3 | P11: 1550 | Q11: UPI | R11: Delivered | S11: Website | T11: 4 | U11: =M11*N11 -> 2499 | V11: =tbl_EcommerceSales[[#This Row],[Gross_Sales]]*tbl_EcommerceSales[[#This Row],[Discount]] -> 749.7 | W11: =tbl_EcommerceSales[[#This Row],[Gross_Sales]]-tbl_EcommerceSales[[#This Row],[Discount_Amount]] -> 1749.3 | X11: =tbl_EcommerceSales[[#This Row],[Quantity]] * _xlfn.XLOOKUP(tbl_EcommerceSales[[#This Row],[Product_ID]], Product_Master!A:A, Product_Master!F:F) -> 1550 | Y11: =tbl_EcommerceSales[[#This Row],[Net_Revenue]]-tbl_EcommerceSales[[#This Row],[Total_Cost]] -> 199.3 | Z11: =IFERROR(#REF!/tbl_EcommerceSales[[#This Row],[Total_Cost]], 0) -> 0 | AA11: =TEXT(tbl_EcommerceSales[[#This Row],[Order_Date]],"mmm") -> Jan | AB11: =YEAR(tbl_EcommerceSales[[#This Row],[Order_Date]]) -> 2025 | AC11: =IF(tbl_EcommerceSales[[#This Row],[Age]]<18,"Under 18",IF(tbl_EcommerceSales[[#This Row],[Age]]<=25,"18-25",IF(tbl_EcommerceSales[[#This Row],[Age]]<=35,"26-35",IF(tbl_EcommerceSales[[#This Row],[Age]]<=45,"36-45",IF(tbl_EcommerceSales[[#This Row],[Age]]<=55,"46-55","56+"))))) -> 36-45
A12: ORD102624 | B12: 45658 | C12: CUST1512 | D12: Sanya Malhotra | E12: Female | F12: 43 | G12: Mumbai | H12: West | I12: P021 | J12: Face Wash | K12: Beauty | L12: Skincare | M12: 2 | N12: 499 | O12: 0.1 | P12: 440 | Q12: Debit Card | R12: Delivered | S12: Mobile App | T12: 4 | U12: =M12*N12 -> 998 | V12: =tbl_EcommerceSales[[#This Row],[Gross_Sales]]*tbl_EcommerceSales[[#This Row],[Discount]] -> 99.8 | W12: =tbl_EcommerceSales[[#This Row],[Gross_Sales]]-tbl_EcommerceSales[[#This Row],[Discount_Amount]] -> 898.2 | X12: =tbl_EcommerceSales[[#This Row],[Quantity]] * _xlfn.XLOOKUP(tbl_EcommerceSales[[#This Row],[Product_ID]], Product_Master!A:A, Product_Master!F:F) -> 440 | Y12: =tbl_EcommerceSales[[#This Row],[Net_Revenue]]-tbl_EcommerceSales[[#This Row],[Total_Cost]] -> 458.2 | Z12: =IFERROR(#REF!/tbl_EcommerceSales[[#This Row],[Total_Cost]], 0) -> 0 | AA12: =TEXT(tbl_EcommerceSales[[#This Row],[Order_Date]],"mmm") -> Jan | AB12: =YEAR(tbl_EcommerceSales[[#This Row],[Order_Date]]) -> 2025 | AC12: =IF(tbl_EcommerceSales[[#This Row],[Age]]<18,"Under 18",IF(tbl_EcommerceSales[[#This Row],[Age]]<=25,"18-25",IF(tbl_EcommerceSales[[#This Row],[Age]]<=35,"26-35",IF(tbl_EcommerceSales[[#This Row],[Age]]<=45,"36-45",IF(tbl_EcommerceSales[[#This Row],[Age]]<=55,"46-55","56+"))))) -> 36-45
A13: ORD103827 | B13: 45658 | C13: CUST0030 | D13: Pooja Kapoor | E13: Female | F13: 36 | G13: Bhubaneswar | H13: East | I13: P007 | J13: Running Shoes | K13: Fashion | L13: Footwear | M13: 1 | N13: 2899 | O13: 0.05 | P13: 1700 | Q13: UPI | R13: Delivered | S13: Website | T13: 5 | U13: =M13*N13 -> 2899 | V13: =tbl_EcommerceSales[[#This Row],[Gross_Sales]]*tbl_EcommerceSales[[#This Row],[Discount]] -> 144.95 | W13: =tbl_EcommerceSales[[#This Row],[Gross_Sales]]-tbl_EcommerceSales[[#This Row],[Discount_Amount]] -> 2754.05 | X13: =tbl_EcommerceSales[[#This Row],[Quantity]] * _xlfn.XLOOKUP(tbl_EcommerceSales[[#This Row],[Product_ID]], Product_Master!A:A, Product_Master!F:F) -> 1700 | Y13: =tbl_EcommerceSales[[#This Row],[Net_Revenue]]-tbl_EcommerceSales[[#This Row],[Total_Cost]] -> 1054.05 | Z13: =IFERROR(#REF!/tbl_EcommerceSales[[#This Row],[Total_Cost]], 0) -> 0 | AA13: =TEXT(tbl_EcommerceSales[[#This Row],[Order_Date]],"mmm") -> Jan | AB13: =YEAR(tbl_EcommerceSales[[#This Row],[Order_Date]]) -> 2025 | AC13: =IF(tbl_EcommerceSales[[#This Row],[Age]]<18,"Under 18",IF(tbl_EcommerceSales[[#This Row],[Age]]<=25,"18-25",IF(tbl_EcommerceSales[[#This Row],[Age]]<=35,"26-35",IF(tbl_EcommerceSales[[#This Row],[Age]]<=45,"36-45",IF(tbl_EcommerceSales[[#This Row],[Age]]<=55,"46-55","56+"))))) -> 36-45
... A26: ORD100661 | B26: 45660 | C26: CUST1356 | D26: Rahul Kumar | E26: Male | F26: 35 | G26: Surat | H26: West | I26: P022 | J26: Sunscreen SPF 50 | K26: Beauty | L26: Skincare | M26: 1 | N26: 799 | O26: 0.1 | P26: 360 | Q26: Net Banking | R26: Delivered | S26: Mobile App | T26: 2 | U26: =M26*N26 -> 799 | V26: =tbl_EcommerceSales[[#This Row],[Gross_Sales]]*tbl_EcommerceSales[[#This Row],[Discount]] -> 79.9 | W26: =tbl_EcommerceSales[[#This Row],[Gross_Sales]]-tbl_EcommerceSales[[#This Row],[Discount_Amount]] -> 719.1 | X26: =tbl_EcommerceSales[[#This Row],[Quantity]] * _xlfn.XLOOKUP(tbl_EcommerceSales[[#This Row],[Product_ID]], Product_Master!A:A, Product_Master!F:F) -> 360 | Y26: =tbl_EcommerceSales[[#This Row],[Net_Revenue]]-tbl_EcommerceSales[[#This Row],[Total_Cost]] -> 359.1 | Z26: =IFERROR(#REF!/tbl_EcommerceSales[[#This Row],[Total_Cost]], 0) -> 0 | AA26: =TEXT(tbl_EcommerceSales[[#This Row],[Order_Date]],"mmm") -> Jan | AB26: =YEAR(tbl_EcommerceSales[[#This Row],[Order_Date]]) -> 2025 | AC26: =IF(tbl_EcommerceSales[[#This Row],[Age]]<18,"Under 18",IF(tbl_EcommerceSales[[#This Row],[Age]]<=25,"18-25",IF(tbl_EcommerceSales[[#This Row],[Age]]<=35,"26-35",IF(tbl_EcommerceSales[[#This Row],[Age]]<=45,"36-45",IF(tbl_EcommerceSales[[#This Row],[Age]]<=55,"46-55","56+"))))) -> 26-35
A27: ORD101122 | B27: 45660 | C27: CUST0253 | D27: Kavya Patel | E27: Female | F27: 32 | G27: Bokaro | H27: East | I27: P028 | J27: Data Analytics Book | K27: Books | L27: Technology | M27: 4 | N27: 1099 | O27: 0.05 | P27: 2080 | Q27: Debit Card | R27: Cancelled | S27: Website | U27: =M27*N27 -> 4396 | V27: =tbl_EcommerceSales[[#This Row],[Gross_Sales]]*tbl_EcommerceSales[[#This Row],[Discount]] -> 219.8 | W27: =tbl_EcommerceSales[[#This Row],[Gross_Sales]]-tbl_EcommerceSales[[#This Row],[Discount_Amount]] -> 4176.2 | X27: =tbl_EcommerceSales[[#This Row],[Quantity]] * _xlfn.XLOOKUP(tbl_EcommerceSales[[#This Row],[Product_ID]], Product_Master!A:A, Product_Master!F:F) -> 2080 | Y27: =tbl_EcommerceSales[[#This Row],[Net_Revenue]]-tbl_EcommerceSales[[#This Row],[Total_Cost]] -> 2096.2 | Z27: =IFERROR(#REF!/tbl_EcommerceSales[[#This Row],[Total_Cost]], 0) -> 0 | AA27: =TEXT(tbl_EcommerceSales[[#This Row],[Order_Date]],"mmm") -> Jan | AB27: =YEAR(tbl_EcommerceSales[[#This Row],[Order_Date]]) -> 2025 | AC27: =IF(tbl_EcommerceSales[[#This Row],[Age]]<18,"Under 18",IF(tbl_EcommerceSales[[#This Row],[Age]]<=25,"18-25",IF(tbl_EcommerceSales[[#This Row],[Age]]<=35,"26-35",IF(tbl_EcommerceSales[[#This Row],[Age]]<=45,"36-45",IF(tbl_EcommerceSales[[#This Row],[Age]]<=55,"46-55","56+"))))) -> 26-35
A28: ORD103448 | B28: 45660 | C28: CUST1478 | D28: Kabir Gupta | E28: Female | F28: 29 | G28: Nashik | H28: West | I28: P024 | J28: Perfume | K28: Beauty | L28: Fragrance | M28: 2 | N28: 1799 | O28: 0.05 | P28: 1800 | Q28: Net Banking | R28: Returned | S28: Mobile App | T28: 4 | U28: =M28*N28 -> 3598 | V28: =tbl_EcommerceSales[[#This Row],[Gross_Sales]]*tbl_EcommerceSales[[#This Row],[Discount]] -> 179.9 | W28: =tbl_EcommerceSales[[#This Row],[Gross_Sales]]-tbl_EcommerceSales[[#This Row],[Discount_Amount]] -> 3418.1 | X28: =tbl_EcommerceSales[[#This Row],[Quantity]] * _xlfn.XLOOKUP(tbl_EcommerceSales[[#This Row],[Product_ID]], Product_Master!A:A, Product_Master!F:F) -> 1800 | Y28: =tbl_EcommerceSales[[#This Row],[Net_Revenue]]-tbl_EcommerceSales[[#This Row],[Total_Cost]] -> 1618.1 | Z28: =IFERROR(#REF!/tbl_EcommerceSales[[#This Row],[Total_Cost]], 0) -> 0 | AA28: =TEXT(tbl_EcommerceSales[[#This Row],[Order_Date]],"mmm") -> Jan | AB28: =YEAR(tbl_EcommerceSales[[#This Row],[Order_Date]]) -> 2025 | AC28: =IF(tbl_EcommerceSales[[#This Row],[Age]]<18,"Under 18",IF(tbl_EcommerceSales[[#This Row],[Age]]<=25,"18-25",IF(tbl_EcommerceSales[[#This Row],[Age]]<=35,"26-35",IF(tbl_EcommerceSales[[#This Row],[Age]]<=45,"36-45",IF(tbl_EcommerceSales[[#This Row],[Age]]<=55,"46-55","56+"))))) -> 26-35
A29: ORD102882 | B29: 45660 | C29: CUST1663 | D29: Shivam Mehta | E29: Female | F29: 29 | G29: Chandigarh | H29: North | I29: P006 | J29: Laptop Backpack | K29: Fashion | L29: Bags | M29: 1 | N29: 1799 | O29: 0.2 | P29: 950 | Q29: UPI | R29: Delivered | S29: Mobile App | T29: 3 | U29: =M29*N29 -> 1799 | V29: =tbl_EcommerceSales[[#This Row],[Gross_Sales]]*tbl_EcommerceSales[[#This Row],[Discount]] -> 359.8 | W29: =tbl_EcommerceSales[[#This Row],[Gross_Sales]]-tbl_EcommerceSales[[#This Row],[Discount_Amount]] -> 1439.2 | X29: =tbl_EcommerceSales[[#This Row],[Quantity]] * _xlfn.XLOOKUP(tbl_EcommerceSales[[#This Row],[Product_ID]], Product_Master!A:A, Product_Master!F:F) -> 950 | Y29: =tbl_EcommerceSales[[#This Row],[Net_Revenue]]-tbl_EcommerceSales[[#This Row],[Total_Cost]] -> 489.2 | Z29: =IFERROR(#REF!/tbl_EcommerceSales[[#This Row],[Total_Cost]], 0) -> 0 | AA29: =TEXT(tbl_EcommerceSales[[#This Row],[Order_Date]],"mmm") -> Jan | AB29: =YEAR(tbl_EcommerceSales[[#This Row],[Order_Date]]) -> 2025 | AC29: =IF(tbl_EcommerceSales[[#This Row],[Age]]<18,"Under 18",IF(tbl_EcommerceSales[[#This Row],[Age]]<=25,"18-25",IF(tbl_EcommerceSales[[#This Row],[Age]]<=35,"26-35",IF(tbl_EcommerceSales[[#This Row],[Age]]<=45,"36-45",IF(tbl_EcommerceSales[[#This Row],[Age]]<=55,"46-55","56+"))))) -> 26-35
A30: ORD101165 | B30: 45660 | C30: CUST0805 | D30: Akash Bansal | E30: Male | F30: 22 | G30: Delhi | H30: North | I30: P020 | J30: Resistance Bands | K30: Sports & Fitness | L30: Fitness | M30: 4 | N30: 699 | O30: 0.1 | P30: 1280 | Q30: Debit Card | R30: Cancelled | S30: Mobile App | U30: =M30*N30 -> 2796 | V30: =tbl_EcommerceSales[[#This Row],[Gross_Sales]]*tbl_EcommerceSales[[#This Row],[Discount]] -> 279.6 | W30: =tbl_EcommerceSales[[#This Row],[Gross_Sales]]-tbl_EcommerceSales[[#This Row],[Discount_Amount]] -> 2516.4 | X30: =tbl_EcommerceSales[[#This Row],[Quantity]] * _xlfn.XLOOKUP(tbl_EcommerceSales[[#This Row],[Product_ID]], Product_Master!A:A, Product_Master!F:F) -> 1280 | Y30: =tbl_EcommerceSales[[#This Row],[Net_Revenue]]-tbl_EcommerceSales[[#This Row],[Total_Cost]] -> 1236.4 | Z30: =IFERROR(#REF!/tbl_EcommerceSales[[#This Row],[Total_Cost]], 0) -> 0 | AA30: =TEXT(tbl_EcommerceSales[[#This Row],[Order_Date]],"mmm") -> Jan | AB30: =YEAR(tbl_EcommerceSales[[#This Row],[Order_Date]]) -> 2025 | AC30: =IF(tbl_EcommerceSales[[#This Row],[Age]]<18,"Under 18",IF(tbl_EcommerceSales[[#This Row],[Age]]<=25,"18-25",IF(tbl_EcommerceSales[[#This Row],[Age]]<=35,"26-35",IF(tbl_EcommerceSales[[#This Row],[Age]]<=45,"36-45",IF(tbl_EcommerceSales[[#This Row],[Age]]<=55,"46-55","56+"))))) -> 18-25
A31: ORD101571 | B31: 45660 | C31: CUST2050 | D31: Manish Agarwal | E31: Female | F31: 23 | G31: Nashik | H31: West | I31: P020 | J31: Resistance Bands | K31: Sports & Fitness | L31: Fitness | M31: 1 | N31: 699 | O31: 0 | P31: 320 | Q31: Net Banking | R31: Delivered | S31: Mobile App | T31: 5 | U31: =M31*N31 -> 699 | V31: =tbl_EcommerceSales[[#This Row],[Gross_Sales]]*tbl_EcommerceSales[[#This Row],[Discount]] -> 0 | W31: =tbl_EcommerceSales[[#This Row],[Gross_Sales]]-tbl_EcommerceSales[[#This Row],[Discount_Amount]] -> 699 | X31: =tbl_EcommerceSales[[#This Row],[Quantity]] * _xlfn.XLOOKUP(tbl_EcommerceSales[[#This Row],[Product_ID]], Product_Master!A:A, Product_Master!F:F) -> 320 | Y31: =tbl_EcommerceSales[[#This Row],[Net_Revenue]]-tbl_EcommerceSales[[#This Row],[Total_Cost]] -> 379 | Z31: =IFERROR(#REF!/tbl_EcommerceSales[[#This Row],[Total_Cost]], 0) -> 0 | AA31: =TEXT(tbl_EcommerceSales[[#This Row],[Order_Date]],"mmm") -> Jan | AB31: =YEAR(tbl_EcommerceSales[[#This Row],[Order_Date]]) -> 2025 | AC31: =IF(tbl_EcommerceSales[[#This Row],[Age]]<18,"Under 18",IF(tbl_EcommerceSales[[#This Row],[Age]]<=25,"18-25",IF(tbl_EcommerceSales[[#This Row],[Age]]<=35,"26-35",IF(tbl_EcommerceSales[[#This Row],[Age]]<=45,"36-45",IF(tbl_EcommerceSales[[#This Row],[Age]]<=55,"46-55","56+"))))) -> 18-25
A32: ORD103305 | B32: 45660 | C32: CUST1100 | D32: Rahul Kumar | E32: Male | F32: 27 | G32: Coimbatore | H32: South | I32: P001 | J32: Wireless Headphones | K32: Electronics | L32: Audio | M32: 1 | N32: 2499 | O32: 0.05 | P32: 1550 | Q32: UPI | R32: Delivered | S32: Website | T32: 5 | U32: =M32*N32 -> 2499 | V32: =tbl_EcommerceSales[[#This Row],[Gross_Sales]]*tbl_EcommerceSales[[#This Row],[Discount]] -> 124.95 | W32: =tbl_EcommerceSales[[#This Row],[Gross_Sales]]-tbl_EcommerceSales[[#This Row],[Discount_Amount]] -> 2374.05 | X32: =tbl_EcommerceSales[[#This Row],[Quantity]] * _xlfn.XLOOKUP(tbl_EcommerceSales[[#This Row],[Product_ID]], Product_Master!A:A, Product_Master!F:F) -> 1550 | Y32: =tbl_EcommerceSales[[#This Row],[Net_Revenue]]-tbl_EcommerceSales[[#This Row],[Total_Cost]] -> 824.05 | Z32: =IFERROR(#REF!/tbl_EcommerceSales[[#This Row],[Total_Cost]], 0) -> 0 | AA32: =TEXT(tbl_EcommerceSales[[#This Row],[Order_Date]],"mmm") -> Jan | AB32: =YEAR(tbl_EcommerceSales[[#This Row],[Order_Date]]) -> 2025 | AC32: =IF(tbl_EcommerceSales[[#This Row],[Age]]<18,"Under 18",IF(tbl_EcommerceSales[[#This Row],[Age]]<=25,"18-25",IF(tbl_EcommerceSales[[#This Row],[Age]]<=35,"26-35",IF(tbl_EcommerceSales[[#This Row],[Age]]<=45,"36-45",IF(tbl_EcommerceSales[[#This Row],[Age]]<=55,"46-55","56+"))))) -> 26-35
A33: ORD104066 | B33: 45661 | C33: CUST2024 | D33: Sanya Malhotra | E33: Female | F33: 18 | G33: Kochi | H33: South | I33: P024 | J33: Perfume | K33: Beauty | L33: Fragrance | M33: 1 | N33: 1799 | O33: 0.1 | P33: 900 | Q33: UPI | R33: Delivered | S33: Mobile App | T33: 3 | U33: =M33*N33 -> 1799 | V33: =tbl_EcommerceSales[[#This Row],[Gross_Sales]]*tbl_EcommerceSales[[#This Row],[Discount]] -> 179.9 | W33: =tbl_EcommerceSales[[#This Row],[Gross_Sales]]-tbl_EcommerceSales[[#This Row],[Discount_Amount]] -> 1619.1 | X33: =tbl_EcommerceSales[[#This Row],[Quantity]] * _xlfn.XLOOKUP(tbl_EcommerceSales[[#This Row],[Product_ID]], Product_Master!A:A, Product_Master!F:F) -> 900 | Y33: =tbl_EcommerceSales[[#This Row],[Net_Revenue]]-tbl_EcommerceSales[[#This Row],[Total_Cost]] -> 719.1 | Z33: =IFERROR(#REF!/tbl_EcommerceSales[[#This Row],[Total_Cost]], 0) -> 0 | AA33: =TEXT(tbl_EcommerceSales[[#This Row],[Order_Date]],"mmm") -> Jan | AB33: =YEAR(tbl_EcommerceSales[[#This Row],[Order_Date]]) -> 2025 | AC33: =IF(tbl_EcommerceSales[[#This Row],[Age]]<18,"Under 18",IF(tbl_EcommerceSales[[#This Row],[Age]]<=25,"18-25",IF(tbl_EcommerceSales[[#This Row],[Age]]<=35,"26-35",IF(tbl_EcommerceSales[[#This Row],[Age]]<=45,"36-45",IF(tbl_EcommerceSales[[#This Row],[Age]]<=55,"46-55","56+"))))) -> 18-25
A34: ORD104229 | B34: 45661 | C34: CUST0960 | D34: Aarav Sharma | E34: Male | F34: 36 | G34: Surat | H34: West | I34: P030 | J34: Self Help Book | K34: Books | L34: Self Development | M34: 4 | N34: 599 | O34: 0.15 | P34: 1040 | Q34: UPI | R34: Delivered | S34: Website | T34: 2 | U34: =M34*N34 -> 2396 | V34: =tbl_EcommerceSales[[#This Row],[Gross_Sales]]*tbl_EcommerceSales[[#This Row],[Discount]] -> 359.4 | W34: =tbl_EcommerceSales[[#This Row],[Gross_Sales]]-tbl_EcommerceSales[[#This Row],[Discount_Amount]] -> 2036.6 | X34: =tbl_EcommerceSales[[#This Row],[Quantity]] * _xlfn.XLOOKUP(tbl_EcommerceSales[[#This Row],[Product_ID]], Product_Master!A:A, Product_Master!F:F) -> 1040 | Y34: =tbl_EcommerceSales[[#This Row],[Net_Revenue]]-tbl_EcommerceSales[[#This Row],[Total_Cost]] -> 996.6 | Z34: =IFERROR(#REF!/tbl_EcommerceSales[[#This Row],[Total_Cost]], 0) -> 0 | AA34: =TEXT(tbl_EcommerceSales[[#This Row],[Order_Date]],"mmm") -> Jan | AB34: =YEAR(tbl_EcommerceSales[[#This Row],[Order_Date]]) -> 2025 | AC34: =IF(tbl_EcommerceSales[[#This Row],[Age]]<18,"Under 18",IF(tbl_EcommerceSales[[#This Row],[Age]]<=25,"18-25",IF(tbl_EcommerceSales[[#This Row],[Age]]<=35,"26-35",IF(tbl_EcommerceSales[[#This Row],[Age]]<=45,"36-45",IF(tbl_EcommerceSales[[#This Row],[Age]]<=55,"46-55","56+"))))) -> 36-45
A35: ORD100717 | B35: 45661 | C35: CUST0460 | D35: Rahul Kumar | E35: Female | F35: 32 | G35: Guwahati | H35: East | I35: P029 | J35: Programming Book | K35: Books | L35: Technology | M35: 1 | N35: 1299 | O35: 0.1 | P35: 610 | Q35: Credit Card | R35: Delivered | S35: Website | T35: 5 | U35: =M35*N35 -> 1299 | V35: =tbl_EcommerceSales[[#This Row],[Gross_Sales]]*tbl_EcommerceSales[[#This Row],[Discount]] -> 129.9 | W35: =tbl_EcommerceSales[[#This Row],[Gross_Sales]]-tbl_EcommerceSales[[#This Row],[Discount_Amount]] -> 1169.1 | X35: =tbl_EcommerceSales[[#This Row],[Quantity]] * _xlfn.XLOOKUP(tbl_EcommerceSales[[#This Row],[Product_ID]], Product_Master!A:A, Product_Master!F:F) -> 610 | Y35: =tbl_EcommerceSales[[#This Row],[Net_Revenue]]-tbl_EcommerceSales[[#This Row],[Total_Cost]] -> 559.1 | Z35: =IFERROR(#REF!/tbl_EcommerceSales[[#This Row],[Total_Cost]], 0) -> 0 | AA35: =TEXT(tbl_EcommerceSales[[#This Row],[Order_Date]],"mmm") -> Jan | AB35: =YEAR(tbl_EcommerceSales[[#This Row],[Order_Date]]) -> 2025 | AC35: =IF(tbl_EcommerceSales[[#This Row],[Age]]<18,"Under 18",IF(tbl_EcommerceSales[[#This Row],[Age]]<=25,"18-25",IF(tbl_EcommerceSales[[#This Row],[Age]]<=35,"26-35",IF(tbl_EcommerceSales[[#This Row],[Age]]<=45,"36-45",IF(tbl_EcommerceSales[[#This Row],[Age]]<=55,"46-55","56+"))))) -> 26-35
A36: ORD100974 | B36: 45661 | C36: CUST0011 | D36: Kiara Chopra | E36: Female | F36: 37 | G36: Kolkata | H36: East | I36: P024 | J36: Perfume | K36: Beauty | L36: Fragrance | M36: 1 | N36: 1799 | O36: 0.2 | P36: 900 | Q36: UPI | R36: Returned | S36: Website | T36: 5 | U36: =M36*N36 -> 1799 | V36: =tbl_EcommerceSales[[#This Row],[Gross_Sales]]*tbl_EcommerceSales[[#This Row],[Discount]] -> 359.8 | W36: =tbl_EcommerceSales[[#This Row],[Gross_Sales]]-tbl_EcommerceSales[[#This Row],[Discount_Amount]] -> 1439.2 | X36: =tbl_EcommerceSales[[#This Row],[Quantity]] * _xlfn.XLOOKUP(tbl_EcommerceSales[[#This Row],[Product_ID]], Product_Master!A:A, Product_Master!F:F) -> 900 | Y36: =tbl_EcommerceSales[[#This Row],[Net_Revenue]]-tbl_EcommerceSales[[#This Row],[Total_Cost]] -> 539.2 | Z36: =IFERROR(#REF!/tbl_EcommerceSales[[#This Row],[Total_Cost]], 0) -> 0 | AA36: =TEXT(tbl_EcommerceSales[[#This Row],[Order_Date]],"mmm") -> Jan | AB36: =YEAR(tbl_EcommerceSales[[#This Row],[Order_Date]]) -> 2025 | AC36: =IF(tbl_EcommerceSales[[#This Row],[Age]]<18,"Under 18",IF(tbl_EcommerceSales[[#This Row],[Age]]<=25,"18-25",IF(tbl_EcommerceSales[[#This Row],[Age]]<=35,"26-35",IF(tbl_EcommerceSales[[#This Row],[Age]]<=45,"36-45",IF(tbl_EcommerceSales[[#This Row],[Age]]<=55,"46-55","56+"))))) -> 36-45
A37: ORD103001 | B37: 45661 | C37: CUST0840 | D37: Sanya Malhotra | E37: Male | F37: 26 | G37: Surat | H37: West | I37: P024 | J37: Perfume | K37: Beauty | L37: Fragrance | M37: 2 | N37: 1799 | O37: 0.2 | P37: 1800 | Q37: UPI | R37: Delivered | S37: Website | T37: 5 | U37: =M37*N37 -> 3598 | V37: =tbl_EcommerceSales[[#This Row],[Gross_Sales]]*tbl_EcommerceSales[[#This Row],[Discount]] -> 719.6 | W37: =tbl_EcommerceSales[[#This Row],[Gross_Sales]]-tbl_EcommerceSales[[#This Row],[Discount_Amount]] -> 2878.4 | X37: =tbl_EcommerceSales[[#This Row],[Quantity]] * _xlfn.XLOOKUP(tbl_EcommerceSales[[#This Row],[Product_ID]], Product_Master!A:A, Product_Master!F:F) -> 1800 | Y37: =tbl_EcommerceSales[[#This Row],[Net_Revenue]]-tbl_EcommerceSales[[#This Row],[Total_Cost]] -> 1078.4 | Z37: =IFERROR(#REF!/tbl_EcommerceSales[[#This Row],[Total_Cost]], 0) -> 0 | AA37: =TEXT(tbl_EcommerceSales[[#This Row],[Order_Date]],"mmm") -> Jan | AB37: =YEAR(tbl_EcommerceSales[[#This Row],[Order_Date]]) -> 2025 | AC37: =IF(tbl_EcommerceSales[[#This Row],[Age]]<18,"Under 18",IF(tbl_EcommerceSales[[#This Row],[Age]]<=25,"18-25",IF(tbl_EcommerceSales[[#This Row],[Age]]<=35,"26-35",IF(tbl_EcommerceSales[[#This Row],[Age]]<=45,"36-45",IF(tbl_EcommerceSales[[#This Row],[Age]]<=55,"46-55","56+"))))) -> 26-35
A38: ORD103955 | B38: 45662 | C38: CUST1401 | D38: Meera Singh | E38: Male | F38: 37 | G38: Kochi | H38: South | I38: P026 | J38: Novel Collection | K38: Books | L38: Fiction | M38: 1 | N38: 899 | O38: 0.05 | P38: 420 | Q38: Credit Card | R38: Delivered | S38: Mobile App | T38: 5 | U38: =M38*N38 -> 899 | V38: =tbl_EcommerceSales[[#This Row],[Gross_Sales]]*tbl_EcommerceSales[[#This Row],[Discount]] -> 44.95 | W38: =tbl_EcommerceSales[[#This Row],[Gross_Sales]]-tbl_EcommerceSales[[#This Row],[Discount_Amount]] -> 854.05 | X38: =tbl_EcommerceSales[[#This Row],[Quantity]] * _xlfn.XLOOKUP(tbl_EcommerceSales[[#This Row],[Product_ID]], Product_Master!A:A, Product_Master!F:F) -> 420 | Y38: =tbl_EcommerceSales[[#This Row],[Net_Revenue]]-tbl_EcommerceSales[[#This Row],[Total_Cost]] -> 434.05 | Z38: =IFERROR(#REF!/tbl_EcommerceSales[[#This Row],[Total_Cost]], 0) -> 0 | AA38: =TEXT(tbl_EcommerceSales[[#This Row],[Order_Date]],"mmm") -> Jan | AB38: =YEAR(tbl_EcommerceSales[[#This Row],[Order_Date]]) -> 2025 | AC38: =IF(tbl_EcommerceSales[[#This Row],[Age]]<18,"Under 18",IF(tbl_EcommerceSales[[#This Row],[Age]]<=25,"18-25",IF(tbl_EcommerceSales[[#This Row],[Age]]<=35,"26-35",IF(tbl_EcommerceSales[[#This Row],[Age]]<=45,"36-45",IF(tbl_EcommerceSales[[#This Row],[Age]]<=55,"46-55","56+"))))) -> 36-45
A39: ORD104005 | B39: 45662 | C39: CUST1988 | D39: Varun Jain | E39: Female | F39: 27 | G39: Kolkata | H39: East | I39: P018 | J39: Cricket Bat | K39: Sports & Fitness | L39: Sports | M39: 1 | N39: 2199 | O39: 0.05 | P39: 1250 | Q39: Credit Card | R39: Delivered | S39: Mobile App | T39: 5 | U39: =M39*N39 -> 2199 | V39: =tbl_EcommerceSales[[#This Row],[Gross_Sales]]*tbl_EcommerceSales[[#This Row],[Discount]] -> 109.95 | W39: =tbl_EcommerceSales[[#This Row],[Gross_Sales]]-tbl_EcommerceSales[[#This Row],[Discount_Amount]] -> 2089.05 | X39: =tbl_EcommerceSales[[#This Row],[Quantity]] * _xlfn.XLOOKUP(tbl_EcommerceSales[[#This Row],[Product_ID]], Product_Master!A:A, Product_Master!F:F) -> 1250 | Y39: =tbl_EcommerceSales[[#This Row],[Net_Revenue]]-tbl_EcommerceSales[[#This Row],[Total_Cost]] -> 839.05 | Z39: =IFERROR(#REF!/tbl_EcommerceSales[[#This Row],[Total_Cost]], 0) -> 0 | AA39: =TEXT(tbl_EcommerceSales[[#This Row],[Order_Date]],"mmm") -> Jan | AB39: =YEAR(tbl_EcommerceSales[[#This Row],[Order_Date]]) -> 2025 | AC39: =IF(tbl_EcommerceSales[[#This Row],[Age]]<18,"Under 18",IF(tbl_EcommerceSales[[#This Row],[Age]]<=25,"18-25",IF(tbl_EcommerceSales[[#This Row],[Age]]<=35,"26-35",IF(tbl_EcommerceSales[[#This Row],[Age]]<=45,"36-45",IF(tbl_EcommerceSales[[#This Row],[Age]]<=55,"46-55","56+"))))) -> 26-35
A40: ORD100306 | B40: 45662 | C40: CUST0421 | D40: Akash Bansal | E40: Female | F40: 44 | G40: Bengaluru | H40: South | I40: P017 | J40: Dumbbell Set | K40: Sports & Fitness | L40: Fitness | M40: 1 | N40: 2499 | O40: 0 | P40: 1450 | Q40: UPI | R40: Delivered | S40: Mobile App | T40: 5 | U40: =M40*N40 -> 2499 | V40: =tbl_EcommerceSales[[#This Row],[Gross_Sales]]*tbl_EcommerceSales[[#This Row],[Discount]] -> 0 | W40: =tbl_EcommerceSales[[#This Row],[Gross_Sales]]-tbl_EcommerceSales[[#This Row],[Discount_Amount]] -> 2499 | X40: =tbl_EcommerceSales[[#This Row],[Quantity]] * _xlfn.XLOOKUP(tbl_EcommerceSales[[#This Row],[Product_ID]], Product_Master!A:A, Product_Master!F:F) -> 1450 | Y40: =tbl_EcommerceSales[[#This Row],[Net_Revenue]]-tbl_EcommerceSales[[#This Row],[Total_Cost]] -> 1049 | Z40: =IFERROR(#REF!/tbl_EcommerceSales[[#This Row],[Total_Cost]], 0) -> 0 | AA40: =TEXT(tbl_EcommerceSales[[#This Row],[Order_Date]],"mmm") -> Jan | AB40: =YEAR(tbl_EcommerceSales[[#This Row],[Order_Date]]) -> 2025 | AC40: =IF(tbl_EcommerceSales[[#This Row],[Age]]<18,"Under 18",IF(tbl_EcommerceSales[[#This Row],[Age]]<=25,"18-25",IF(tbl_EcommerceSales[[#This Row],[Age]]<=35,"26-35",IF(tbl_EcommerceSales[[#This Row],[Age]]<=45,"36-45",IF(tbl_EcommerceSales[[#This Row],[Age]]<=55,"46-55","56+"))))) -> 36-45
A41: ORD103908 | B41: 45662 | C41: CUST0731 | D41: Vansh Chopra | E41: Male | F41: 35 | G41: Nashik | H41: West | I41: P008 | J41: Cotton T-Shirt | K41: Fashion | L41: Clothing | M41: 1 | N41: 799 | O41: 0.1 | P41: 390 | Q41: UPI | R41: Delivered | S41: Website | T41: 3 | U41: =M41*N41 -> 799 | V41: =tbl_EcommerceSales[[#This Row],[Gross_Sales]]*tbl_EcommerceSales[[#This Row],[Discount]] -> 79.9 | W41: =tbl_EcommerceSales[[#This Row],[Gross_Sales]]-tbl_EcommerceSales[[#This Row],[Discount_Amount]] -> 719.1 | X41: =tbl_EcommerceSales[[#This Row],[Quantity]] * _xlfn.XLOOKUP(tbl_EcommerceSales[[#This Row],[Product_ID]], Product_Master!A:A, Product_Master!F:F) -> 390 | Y41: =tbl_EcommerceSales[[#This Row],[Net_Revenue]]-tbl_EcommerceSales[[#This Row],[Total_Cost]] -> 329.1 | Z41: =IFERROR(#REF!/tbl_EcommerceSales[[#This Row],[Total_Cost]], 0) -> 0 | AA41: =TEXT(tbl_EcommerceSales[[#This Row],[Order_Date]],"mmm") -> Jan | AB41: =YEAR(tbl_EcommerceSales[[#This Row],[Order_Date]]) -> 2025 | AC41: =IF(tbl_EcommerceSales[[#This Row],[Age]]<18,"Under 18",IF(tbl_EcommerceSales[[#This Row],[Age]]<=25,"18-25",IF(tbl_EcommerceSales[[#This Row],[Age]]<=35,"26-35",IF(tbl_EcommerceSales[[#This Row],[Age]]<=45,"36-45",IF(tbl_EcommerceSales[[#This Row],[Age]]<=55,"46-55","56+"))))) -> 26-35
A42: ORD102867 | B42: 45662 | C42: CUST0859 | D42: Vansh Chopra | E42: Female | F42: 33 | G42: Dehradun | H42: North | I42: P021 | J42: Face Wash | K42: Beauty | L42: Skincare | M42: 1 | N42: 499 | O42: 0.15 | P42: 220 | Q42: UPI | R42: Delivered | S42: Website | T42: 5 | U42: =M42*N42 -> 499 | V42: =tbl_EcommerceSales[[#This Row],[Gross_Sales]]*tbl_EcommerceSales[[#This Row],[Discount]] -> 74.85 | W42: =tbl_EcommerceSales[[#This Row],[Gross_Sales]]-tbl_EcommerceSales[[#This Row],[Discount_Amount]] -> 424.15 | X42: =tbl_EcommerceSales[[#This Row],[Quantity]] * _xlfn.XLOOKUP(tbl_EcommerceSales[[#This Row],[Product_ID]], Product_Master!A:A, Product_Master!F:F) -> 220 | Y42: =tbl_EcommerceSales[[#This Row],[Net_Revenue]]-tbl_EcommerceSales[[#This Row],[Total_Cost]] -> 204.15 | Z42: =IFERROR(#REF!/tbl_EcommerceSales[[#This Row],[Total_Cost]], 0) -> 0 | AA42: =TEXT(tbl_EcommerceSales[[#This Row],[Order_Date]],"mmm") -> Jan | AB42: =YEAR(tbl_EcommerceSales[[#This Row],[Order_Date]]) -> 2025 | AC42: =IF(tbl_EcommerceSales[[#This Row],[Age]]<18,"Under 18",IF(tbl_EcommerceSales[[#This Row],[Age]]<=25,"18-25",IF(tbl_EcommerceSales[[#This Row],[Age]]<=35,"26-35",IF(tbl_EcommerceSales[[#This Row],[Age]]<=45,"36-45",IF(tbl_EcommerceSales[[#This Row],[Age]]<=55,"46-55","56+"))))) -> 26-35
... A100: ORD101578 | B100: 45669 | C100: CUST0669 | D100: Kavya Patel | E100: Male | F100: 30 | G100: Delhi | H100: North | I100: P030 | J100: Self Help Book | K100: Books | L100: Self Development | M100: 1 | N100: 599 | O100: 0.05 | P100: 260 | Q100: Cash on Delivery | R100: Returned | S100: Mobile App | T100: 5 | U100: =M100*N100 -> 599 | V100: =tbl_EcommerceSales[[#This Row],[Gross_Sales]]*tbl_EcommerceSales[[#This Row],[Discount]] -> 29.95 | W100: =tbl_EcommerceSales[[#This Row],[Gross_Sales]]-tbl_EcommerceSales[[#This Row],[Discount_Amount]] -> 569.05 | X100: =tbl_EcommerceSales[[#This Row],[Quantity]] * _xlfn.XLOOKUP(tbl_EcommerceSales[[#This Row],[Product_ID]], Product_Master!A:A, Product_Master!F:F) -> 260 | Y100: =tbl_EcommerceSales[[#This Row],[Net_Revenue]]-tbl_EcommerceSales[[#This Row],[Total_Cost]] -> 309.05 | Z100: =IFERROR(#REF!/tbl_EcommerceSales[[#This Row],[Total_Cost]], 0) -> 0 | AA100: =TEXT(tbl_EcommerceSales[[#This Row],[Order_Date]],"mmm") -> Jan | AB100: =YEAR(tbl_EcommerceSales[[#This Row],[Order_Date]]) -> 2025 | AC100: =IF(tbl_EcommerceSales[[#This Row],[Age]]<18,"Under 18",IF(tbl_EcommerceSales[[#This Row],[Age]]<=25,"18-25",IF(tbl_EcommerceSales[[#This Row],[Age]]<=35,"26-35",IF(tbl_EcommerceSales[[#This Row],[Age]]<=45,"36-45",IF(tbl_EcommerceSales[[#This Row],[Age]]<=55,"46-55","56+"))))) -> 26-35
A101: ORD102698 | B101: 45669 | C101: CUST2127 | D101: Isha Mehta | E101: Male | F101: 33 | G101: Surat | H101: West | I101: P009 | J101: Denim Jeans | K101: Fashion | L101: Clothing | M101: 1 | N101: 1999 | O101: 0.1 | P101: 1050 | Q101: Debit Card | R101: Cancelled | S101: Mobile App | U101: =M101*N101 -> 1999 | V101: =tbl_EcommerceSales[[#This Row],[Gross_Sales]]*tbl_EcommerceSales[[#This Row],[Discount]] -> 199.9 | W101: =tbl_EcommerceSales[[#This Row],[Gross_Sales]]-tbl_EcommerceSales[[#This Row],[Discount_Amount]] -> 1799.1 | X101: =tbl_EcommerceSales[[#This Row],[Quantity]] * _xlfn.XLOOKUP(tbl_EcommerceSales[[#This Row],[Product_ID]], Product_Master!A:A, Product_Master!F:F) -> 1050 | Y101: =tbl_EcommerceSales[[#This Row],[Net_Revenue]]-tbl_EcommerceSales[[#This Row],[Total_Cost]] -> 749.1 | Z101: =IFERROR(#REF!/tbl_EcommerceSales[[#This Row],[Total_Cost]], 0) -> 0 | AA101: =TEXT(tbl_EcommerceSales[[#This Row],[Order_Date]],"mmm") -> Jan | AB101: =YEAR(tbl_EcommerceSales[[#This Row],[Order_Date]]) -> 2025 | AC101: =IF(tbl_EcommerceSales[[#This Row],[Age]]<18,"Under 18",IF(tbl_EcommerceSales[[#This Row],[Age]]<=25,"18-25",IF(tbl_EcommerceSales[[#This Row],[Age]]<=35,"26-35",IF(tbl_EcommerceSales[[#This Row],[Age]]<=45,"36-45",IF(tbl_EcommerceSales[[#This Row],[Age]]<=55,"46-55","56+"))))) -> 26-35
A102: ORD104272 | B102: 45669 | C102: CUST2008 | D102: Ishaan Malhotra | E102: Male | F102: 39 | G102: Delhi | H102: North | I102: P007 | J102: Running Shoes | K102: Fashion | L102: Footwear | M102: 1 | N102: 2899 | O102: 0.1 | P102: 1700 | Q102: Wallet | R102: Delivered | S102: Mobile App | T102: 5 | U102: =M102*N102 -> 2899 | V102: =tbl_EcommerceSales[[#This Row],[Gross_Sales]]*tbl_EcommerceSales[[#This Row],[Discount]] -> 289.9 | W102: =tbl_EcommerceSales[[#This Row],[Gross_Sales]]-tbl_EcommerceSales[[#This Row],[Discount_Amount]] -> 2609.1 | X102: =tbl_EcommerceSales[[#This Row],[Quantity]] * _xlfn.XLOOKUP(tbl_EcommerceSales[[#This Row],[Product_ID]], Product_Master!A:A, Product_Master!F:F) -> 1700 | Y102: =tbl_EcommerceSales[[#This Row],[Net_Revenue]]-tbl_EcommerceSales[[#This Row],[Total_Cost]] -> 909.1 | Z102: =IFERROR(#REF!/tbl_EcommerceSales[[#This Row],[Total_Cost]], 0) -> 0 | AA102: =TEXT(tbl_EcommerceSales[[#This Row],[Order_Date]],"mmm") -> Jan | AB102: =YEAR(tbl_EcommerceSales[[#This Row],[Order_Date]]) -> 2025 | AC102: =IF(tbl_EcommerceSales[[#This Row],[Age]]<18,"Under 18",IF(tbl_EcommerceSales[[#This Row],[Age]]<=25,"18-25",IF(tbl_EcommerceSales[[#This Row],[Age]]<=35,"26-35",IF(tbl_EcommerceSales[[#This Row],[Age]]<=45,"36-45",IF(tbl_EcommerceSales[[#This Row],[Age]]<=55,"46-55","56+"))))) -> 36-45
A103: ORD103128 | B103: 45669 | C103: CUST0530 | D103: Yash Agarwal | E103: Male | F103: 35 | G103: Kochi | H103: South | I103: P008 | J103: Cotton T-Shirt | K103: Fashion | L103: Clothing | M103: 1 | N103: 799 | O103: 0.1 | P103: 390 | Q103: Credit Card | R103: Delivered | S103: Website | T103: 4 | U103: =M103*N103 -> 799 | V103: =tbl_EcommerceSales[[#This Row],[Gross_Sales]]*tbl_EcommerceSales[[#This Row],[Discount]] -> 79.9 | W103: =tbl_EcommerceSales[[#This Row],[Gross_Sales]]-tbl_EcommerceSales[[#This Row],[Discount_Amount]] -> 719.1 | X103: =tbl_EcommerceSales[[#This Row],[Quantity]] * _xlfn.XLOOKUP(tbl_EcommerceSales[[#This Row],[Product_ID]], Product_Master!A:A, Product_Master!F:F) -> 390 | Y103: =tbl_EcommerceSales[[#This Row],[Net_Revenue]]-tbl_EcommerceSales[[#This Row],[Total_Cost]] -> 329.1 | Z103: =IFERROR(#REF!/tbl_EcommerceSales[[#This Row],[Total_Cost]], 0) -> 0 | AA103: =TEXT(tbl_EcommerceSales[[#This Row],[Order_Date]],"mmm") -> Jan | AB103: =YEAR(tbl_EcommerceSales[[#This Row],[Order_Date]]) -> 2025 | AC103: =IF(tbl_EcommerceSales[[#This Row],[Age]]<18,"Under 18",IF(tbl_EcommerceSales[[#This Row],[Age]]<=25,"18-25",IF(tbl_EcommerceSales[[#This Row],[Age]]<=35,"26-35",IF(tbl_EcommerceSales[[#This Row],[Age]]<=45,"36-45",IF(tbl_EcommerceSales[[#This Row],[Age]]<=55,"46-55","56+"))))) -> 26-35
A104: ORD104246 | B104: 45669 | C104: CUST1268 | D104: Karan Jain | E104: Female | F104: 40 | G104: Pune | H104: West | I104: P005 | J104: Power Bank 20000mAh | K104: Electronics | L104: Accessories | M104: 3 | N104: 1599 | O104: 0.15 | P104: 2760 | Q104: Net Banking | R104: Delivered | S104: Mobile App | T104: 4 | U104: =M104*N104 -> 4797 | V104: =tbl_EcommerceSales[[#This Row],[Gross_Sales]]*tbl_EcommerceSales[[#This Row],[Discount]] -> 719.55 | W104: =tbl_EcommerceSales[[#This Row],[Gross_Sales]]-tbl_EcommerceSales[[#This Row],[Discount_Amount]] -> 4077.45 | X104: =tbl_EcommerceSales[[#This Row],[Quantity]] * _xlfn.XLOOKUP(tbl_EcommerceSales[[#This Row],[Product_ID]], Product_Master!A:A, Product_Master!F:F) -> 2760 | Y104: =tbl_EcommerceSales[[#This Row],[Net_Revenue]]-tbl_EcommerceSales[[#This Row],[Total_Cost]] -> 1317.45 | Z104: =IFERROR(#REF!/tbl_EcommerceSales[[#This Row],[Total_Cost]], 0) -> 0 | AA104: =TEXT(tbl_EcommerceSales[[#This Row],[Order_Date]],"mmm") -> Jan | AB104: =YEAR(tbl_EcommerceSales[[#This Row],[Order_Date]]) -> 2025 | AC104: =IF(tbl_EcommerceSales[[#This Row],[Age]]<18,"Under 18",IF(tbl_EcommerceSales[[#This Row],[Age]]<=25,"18-25",IF(tbl_EcommerceSales[[#This Row],[Age]]<=35,"26-35",IF(tbl_EcommerceSales[[#This Row],[Age]]<=45,"36-45",IF(tbl_EcommerceSales[[#This Row],[Age]]<=55,"46-55","56+"))))) -> 36-45
A105: ORD101389 | B105: 45669 | C105: CUST0168 | D105: Sanya Malhotra | E105: Male | F105: 38 | G105: Ranchi | H105: East | I105: P024 | J105: Perfume | K105: Beauty | L105: Fragrance | M105: 1 | N105: 1799 | O105: 0.1 | P105: 900 | Q105: Credit Card | R105: Delivered | S105: Website | T105: 5 | U105: =M105*N105 -> 1799 | V105: =tbl_EcommerceSales[[#This Row],[Gross_Sales]]*tbl_EcommerceSales[[#This Row],[Discount]] -> 179.9 | W105: =tbl_EcommerceSales[[#This Row],[Gross_Sales]]-tbl_EcommerceSales[[#This Row],[Discount_Amount]] -> 1619.1 | X105: =tbl_EcommerceSales[[#This Row],[Quantity]] * _xlfn.XLOOKUP(tbl_EcommerceSales[[#This Row],[Product_ID]], Product_Master!A:A, Product_Master!F:F) -> 900 | Y105: =tbl_EcommerceSales[[#This Row],[Net_Revenue]]-tbl_EcommerceSales[[#This Row],[Total_Cost]] -> 719.1 | Z105: =IFERROR(#REF!/tbl_EcommerceSales[[#This Row],[Total_Cost]], 0) -> 0 | AA105: =TEXT(tbl_EcommerceSales[[#This Row],[Order_Date]],"mmm") -> Jan | AB105: =YEAR(tbl_EcommerceSales[[#This Row],[Order_Date]]) -> 2025 | AC105: =IF(tbl_EcommerceSales[[#This Row],[Age]]<18,"Under 18",IF(tbl_EcommerceSales[[#This Row],[Age]]<=25,"18-25",IF(tbl_EcommerceSales[[#This Row],[Age]]<=35,"26-35",IF(tbl_EcommerceSales[[#This Row],[Age]]<=45,"36-45",IF(tbl_EcommerceSales[[#This Row],[Age]]<=55,"46-55","56+"))))) -> 36-45
A106: ORD100372 | B106: 45669 | C106: CUST1974 | D106: Simran Gupta | E106: Female | F106: 33 | G106: Kochi | H106: South | I106: P026 | J106: Novel Collection | K106: Books | L106: Fiction | M106: 1 | N106: 899 | O106: 0.2 | P106: 420 | Q106: Credit Card | R106: Delivered | S106: Website | T106: 3 | U106: =M106*N106 -> 899 | V106: =tbl_EcommerceSales[[#This Row],[Gross_Sales]]*tbl_EcommerceSales[[#This Row],[Discount]] -> 179.8 | W106: =tbl_EcommerceSales[[#This Row],[Gross_Sales]]-tbl_EcommerceSales[[#This Row],[Discount_Amount]] -> 719.2 | X106: =tbl_EcommerceSales[[#This Row],[Quantity]] * _xlfn.XLOOKUP(tbl_EcommerceSales[[#This Row],[Product_ID]], Product_Master!A:A, Product_Master!F:F) -> 420 | Y106: =tbl_EcommerceSales[[#This Row],[Net_Revenue]]-tbl_EcommerceSales[[#This Row],[Total_Cost]] -> 299.2 | Z106: =IFERROR(#REF!/tbl_EcommerceSales[[#This Row],[Total_Cost]], 0) -> 0 | AA106: =TEXT(tbl_EcommerceSales[[#This Row],[Order_Date]],"mmm") -> Jan | AB106: =YEAR(tbl_EcommerceSales[[#This Row],[Order_Date]]) -> 2025 | AC106: =IF(tbl_EcommerceSales[[#This Row],[Age]]<18,"Under 18",IF(tbl_EcommerceSales[[#This Row],[Age]]<=25,"18-25",IF(tbl_EcommerceSales[[#This Row],[Age]]<=35,"26-35",IF(tbl_EcommerceSales[[#This Row],[Age]]<=45,"36-45",IF(tbl_EcommerceSales[[#This Row],[Age]]<=55,"46-55","56+"))))) -> 26-35
A107: ORD101706 | B107: 45669 | C107: CUST2101 | D107: Pranav Bansal | E107: Male | F107: 26 | G107: Dehradun | H107: North | I107: P002 | J107: Bluetooth Speaker | K107: Electronics | L107: Audio | M107: 3 | N107: 1899 | O107: 0 | P107: 3360 | Q107: Net Banking | R107: Delivered | S107: Website | T107: 3 | U107: =M107*N107 -> 5697 | V107: =tbl_EcommerceSales[[#This Row],[Gross_Sales]]*tbl_EcommerceSales[[#This Row],[Discount]] -> 0 | W107: =tbl_EcommerceSales[[#This Row],[Gross_Sales]]-tbl_EcommerceSales[[#This Row],[Discount_Amount]] -> 5697 | X107: =tbl_EcommerceSales[[#This Row],[Quantity]] * _xlfn.XLOOKUP(tbl_EcommerceSales[[#This Row],[Product_ID]], Product_Master!A:A, Product_Master!F:F) -> 3360 | Y107: =tbl_EcommerceSales[[#This Row],[Net_Revenue]]-tbl_EcommerceSales[[#This Row],[Total_Cost]] -> 2337 | Z107: =IFERROR(#REF!/tbl_EcommerceSales[[#This Row],[Total_Cost]], 0) -> 0 | AA107: =TEXT(tbl_EcommerceSales[[#This Row],[Order_Date]],"mmm") -> Jan | AB107: =YEAR(tbl_EcommerceSales[[#This Row],[Order_Date]]) -> 2025 | AC107: =IF(tbl_EcommerceSales[[#This Row],[Age]]<18,"Under 18",IF(tbl_EcommerceSales[[#This Row],[Age]]<=25,"18-25",IF(tbl_EcommerceSales[[#This Row],[Age]]<=35,"26-35",IF(tbl_EcommerceSales[[#This Row],[Age]]<=45,"36-45",IF(tbl_EcommerceSales[[#This Row],[Age]]<=55,"46-55","56+"))))) -> 26-35
A108: ORD104600 | B108: 45669 | C108: CUST1608 | D108: Sanya Malhotra | E108: Male | F108: 27 | G108: Mysuru | H108: South | I108: P018 | J108: Cricket Bat | K108: Sports & Fitness | L108: Sports | M108: 2 | N108: 2199 | O108: 0 | P108: 2500 | Q108: Cash on Delivery | R108: Delivered | S108: Mobile App | T108: 4 | U108: =M108*N108 -> 4398 | V108: =tbl_EcommerceSales[[#This Row],[Gross_Sales]]*tbl_EcommerceSales[[#This Row],[Discount]] -> 0 | W108: =tbl_EcommerceSales[[#This Row],[Gross_Sales]]-tbl_EcommerceSales[[#This Row],[Discount_Amount]] -> 4398 | X108: =tbl_EcommerceSales[[#This Row],[Quantity]] * _xlfn.XLOOKUP(tbl_EcommerceSales[[#This Row],[Product_ID]], Product_Master!A:A, Product_Master!F:F) -> 2500 | Y108: =tbl_EcommerceSales[[#This Row],[Net_Revenue]]-tbl_EcommerceSales[[#This Row],[Total_Cost]] -> 1898 | Z108: =IFERROR(#REF!/tbl_EcommerceSales[[#This Row],[Total_Cost]], 0) -> 0 | AA108: =TEXT(tbl_EcommerceSales[[#This Row],[Order_Date]],"mmm") -> Jan | AB108: =YEAR(tbl_EcommerceSales[[#This Row],[Order_Date]]) -> 2025 | AC108: =IF(tbl_EcommerceSales[[#This Row],[Age]]<18,"Under 18",IF(tbl_EcommerceSales[[#This Row],[Age]]<=25,"18-25",IF(tbl_EcommerceSales[[#This Row],[Age]]<=35,"26-35",IF(tbl_EcommerceSales[[#This Row],[Age]]<=45,"36-45",IF(tbl_EcommerceSales[[#This Row],[Age]]<=55,"46-55","56+"))))) -> 26-35
A109: ORD101746 | B109: 45669 | C109: CUST1944 | D109: Ishaan Malhotra | E109: Female | F109: 29 | G109: Dehradun | H109: North | I109: P013 | J109: Non-Stick Cookware Set | K109: Home & Kitchen | L109: Cookware | M109: 1 | N109: 4299 | O109: 0.15 | P109: 2700 | Q109: Debit Card | R109: Returned | S109: Website | T109: 2 | U109: =M109*N109 -> 4299 | V109: =tbl_EcommerceSales[[#This Row],[Gross_Sales]]*tbl_EcommerceSales[[#This Row],[Discount]] -> 644.85 | W109: =tbl_EcommerceSales[[#This Row],[Gross_Sales]]-tbl_EcommerceSales[[#This Row],[Discount_Amount]] -> 3654.15 | X109: =tbl_EcommerceSales[[#This Row],[Quantity]] * _xlfn.XLOOKUP(tbl_EcommerceSales[[#This Row],[Product_ID]], Product_Master!A:A, Product_Master!F:F) -> 2700 | Y109: =tbl_EcommerceSales[[#This Row],[Net_Revenue]]-tbl_EcommerceSales[[#This Row],[Total_Cost]] -> 954.15 | Z109: =IFERROR(#REF!/tbl_EcommerceSales[[#This Row],[Total_Cost]], 0) -> 0 | AA109: =TEXT(tbl_EcommerceSales[[#This Row],[Order_Date]],"mmm") -> Jan | AB109: =YEAR(tbl_EcommerceSales[[#This Row],[Order_Date]]) -> 2025 | AC109: =IF(tbl_EcommerceSales[[#This Row],[Age]]<18,"Under 18",IF(tbl_EcommerceSales[[#This Row],[Age]]<=25,"18-25",IF(tbl_EcommerceSales[[#This Row],[Age]]<=35,"26-35",IF(tbl_EcommerceSales[[#This Row],[Age]]<=45,"36-45",IF(tbl_EcommerceSales[[#This Row],[Age]]<=55,"46-55","56+"))))) -> 26-35
...

Sheet Product_Master
A1: Product_ID | B1: Product_Name | C1: Category | D1: Sub_Category | E1: Unit_Price | F1: Unit_Cost
A2: P001 | B2: Wireless Headphones | C2: Electronics | D2: Audio | E2: 2499 | F2: 1550
A3: P002 | B3: Bluetooth Speaker | C3: Electronics | D3: Audio | E3: 1899 | F3: 1120
A4: P003 | B4: Smart Watch | C4: Electronics | D4: Wearables | E4: 3299 | F4: 2100
A5: P004 | B5: USB-C Charger | C5: Electronics | D5: Accessories | E5: 899 | F5: 480
A6: P005 | B6: Power Bank 20000mAh | C6: Electronics | D6: Accessories | E6: 1599 | F6: 920
A7: P006 | B7: Laptop Backpack | C7: Fashion | D7: Bags | E7: 1799 | F7: 950
A8: P007 | B8: Running Shoes | C8: Fashion | D8: Footwear | E8: 2899 | F8: 1700
A9: P008 | B9: Cotton T-Shirt | C9: Fashion | D9: Clothing | E9: 799 | F9: 390
A10: P009 | B10: Denim Jeans | C10: Fashion | D10: Clothing | E10: 1999 | F10: 1050
A11: P010 | B11: Casual Hoodie | C11: Fashion | D11: Clothing | E11: 1499 | F11: 780
A12: P011 | B12: Coffee Maker | C12: Home & Kitchen | D12: Kitchen | E12: 3499 | F12: 2250
A13: P012 | B13: Air Fryer | C13: Home & Kitchen | D13: Kitchen | E13: 5999 | F13: 3900
... A31: P030 | B31: Self Help Book | C31: Books | D31: Self Development | E31: 599 | F31: 260

Sheet Data_Dictionary
A1: Column | B1: Description
A2: Order_ID | B2: Unique order identifier
A3: Order_Date | B3: Date the order was placed
A4: Customer_ID | B4: Unique customer identifier
A5: Customer_Name | B5: Customer full name
A6: Gender | B6: Customer gender
A7: Age | B7: Customer age
A8: City | B8: Customer city
A9: Region | B9: Customer region
A10: Product_ID | B10: Unique product identifier
A11: Product_Name | B11: Product name
